Workbook

Sheet Sheet1
E17: FINANCIAL STATEMENT ANALYSIS
E20: Sumitted By- | I20: Submitted To - | J20: Prof. Pankaj
E22: Learning Team 8
E23: S. No. | F23: Roll No. | G23: Name
E24: 1 | F24: 25PGDM236 | G24: Anant Singhal
E25: 2 | F25: 25PGDM197 | G25: Hardik Rawat
E26: 3 | F26: 25PGDM185 | G26: Aman Mishra
E27: 4 | F27: 25PGDM214 | G27: Prince Ranjan
E28: 5 | F28: 25PGDM192 | G28: Deepak kuman sharma

Sheet _RawData
A1: Profit and Loss | B1: FY2021 | C1: FY2022 | D1: FY2023 | E1: FY2024 | F1: FY2025 | H1: Balance Sheet | I1: FY2021 | J1: FY2022 | K1: FY2023 | L1: FY2024 | M1: FY2025 | O1: Cash Flow Statements | P1: FY2021 | Q1: FY2022 | R1: FY2023 | S1: FY2024 | T1: FY2025
A2: Revenue | B2: 5541 | C2: 6311 | D2: 7140 | E2: 7493 | F2: 8294 | H2: Cash & Equivalents | I2: 1326 | J2: 1307 | K2: 2298 | L2: 1533 | M2: 2088 | O2: Net Income | P2: 1377 | Q2: 1192 | R2: 1631 | S2: 1509 | T2: 1905
A3: Cost of Revenue | B3: 2433 | C3: 3136 | D3: 3346 | E3: 3444 | F3: 3662 | H3: Short-Term Investments | I3: 1750 | J3: 1362 | K3: 955.61 | L3: 0 | M3: 677.08 | O3: D&A | P3: 50.16 | Q3: 61.24 | R3: 68.9 | S3: 80.43 | T3: 114.44
A4: Gross Profit | B4: 3109 | C4: 3175 | D4: 3794 | E4: 4049 | F4: 4632 | H4: Cash & Short-Term Investments | I4: 3076 | J4: 2669 | K4: 3253 | L4: 1533 | M4: 2765 | O4: Stock-Based Compensation | P4: 70.48 | Q4: 64.11 | R4: 68.84 | S4: 90.99 | T4: 125.69
A5: Other Operating Expenses | B5: 1311 | C5: 1590 | D5: 1841 | E5: 2119 | F5: 2213 | H5: Accounts Receivable | I5: 896.66 | J5: 1016 | K5: 1194 | L5: 1222 | M5: 1618 | O5: Other Adjustments | P5: 19.52 | Q5: 57.53 | R5: -21.61 | S5: 170.94 | T5: 72.83
A6: Operating Income | B6: 1797 | C6: 1585 | D6: 1953 | E6: 1930 | F6: 2419 | H6: Inventory | I6: 593.36 | J6: 935.63 | K6: 971.41 | L6: 737.11 | M6: 799.62 | O6: Change in Receivables | P6: -254.23 | Q6: -128.98 | R6: -163.16 | S6: -93.92 | T6: -300.6
A7: Interest Income | B7: 3.95 | C7: -12.76 | D7: 115.13 | E7: 59.17 | F7: 63.18 | H7: Other Current Assets | I7: 115.91 | J7: 143.61 | K7: 170.35 | L7: 149.46 | M7: 178.19 | O7: Changes in Inventories | P7: -277.79 | Q7: -347.71 | R7: 7.9 | S7: 211.5 | T7: -34.92
A8: Pretax Income | B8: 1801 | C8: 1572 | D8: 2068 | E8: 1989 | F8: 2483 | H8: Total Current Assets | I8: 4682 | J8: 4765 | K8: 5589 | L8: 3642 | M8: 5361 | O8: Changes in Accounts Payable | P8: 114.3 | Q8: 49.77 | R8: 112.79 | S8: -61.49 | T8: 78.46
A9: Provision for Income Taxes | B9: 423.94 | C9: 380.34 | D9: 437.49 | E9: 480.41 | F9: 577.1 | H9: Net PP&E | I9: 313.75 | J9: 516.9 | K9: 890.8 | L9: 1047 | M9: 1082 | O9: Changes in Accrued Expenses | P9: 111.13 | Q9: 24.13 | R9: 11.42 | S9: 34.05 | T9: 197.41
A10: Net Income | B10: 1377 | C10: 1192 | D10: 1631 | E10: 1509 | F10: 1905 | H10: Other Intangible Assets | I10: 1072 | J10: 1220 | K10: 1427 | L10: 1414 | M10: 1379 | O10: Changes in Income Taxes Payable | P10: 7.23 | Q10: -16.86 | R10: 1.75 | S10: 9.44 | T10: 27.78
A11: Shares Outstanding (Diluted) | B11: 1071 | C11: 1066 | D11: 1058 | E11: 1013 | F11: 984 | H11: Goodwill | I11: 1332 | J11: 1418 | K11: 1418 | L11: 1332 | M11: 1332 | O11: Changes in Unearned Revenue | P11: -22.66 | Q11: -19.91 | R11: -24.47 | S11: -17.36 | T11: -23.01
A12: EPS (Diluted) | B12: 1.29 | C12: 1.12 | D12: 1.54 | E12: 1.49 | F12: 1.94 | H12: Long-Term Investments | I12: 99.42 | J12: 61.44 | K12: 76.43 | L12: 0 | M12: 487.33 | O12: Other Operating Activities | P12: -39.77 | Q12: -47.25 | R12: -6.1 | S12: 25.41 | T12: -65.34
A13: EBITDA | B13: 1848 | C13: 1646 | D13: 2022 | E13: 2011 | F13: 2534 | H13: Other Long-Term Assets | I13: 305.47 | J13: 311.52 | K13: 285.22 | L13: 284.67 | M13: 348.08 | O13: Operating Cash Flow | P13: 1156 | Q13: 887.7 | R13: 1718 | S13: 1929 | T13: 2098
... A15: Free Cash Flow | B15: 1112 | C15: 698.97 | D15: 1496 | E15: 1664 | F15: 1966 | H15: Accounts Payable | I15: 404.26 | J15: 444.27 | K15: 564.38 | L15: 466.78 | M15: 565.97 | O15: Sale of PP&E | P15: 1.33 | Q15: 1.31 | R15: 2.52 | S15: 2.73 | T15: 4.3
H16: Accrued Expenses | I16: 487.88 | J16: 501.09 | K16: 540.44 | L16: 580.93 | M16: 804.18 | O16: Purchases of Intangible Assets | P16: -13.59 | Q16: -23.43 | R16: -13.3 | S16: -42.36 | T16: -25.25
H17: Unearned Revenue | I17: 42.53 | J17: 43.31 | K17: 41.91 | L17: 45.81 | M17: 45.32 | O17: Purchases of Investments | P17: -2413 | Q17: -1847 | R17: -1621 | S17: -342.12 | T17: -1269
H18: Other Current Liabilities | I18: 30.4 | J18: 13.32 | K18: 14.96 | L18: 4.01 | M18: 32.31 | O18: Proceeds from Sale of Investments | P18: 1489 | Q18: 2252 | R18: 2030 | S18: 1378 | T18: 105.79
H19: Total Current Liabilities | I19: 965.08 | J19: 1002 | K19: 1162 | L19: 1098 | M19: 1448 | O19: Business Acquisitions | P19: 0 | Q19: -329.47 | R19: -363.39 | S19: 0 | T19: 0
H20: Long-Term Debt | I20: 0 | J20: 0 | K20: 0 | L20: 373.95 | M20: 0 | O20: Other Investing Activities | P20: -11.35 | Q20: -26.34 | R20: -6.83 | S20: 1.64 | T20: -0.4
H21: Other Long-Term Liabilities | I21: 272.76 | J21: 266.09 | K21: 296.09 | L21: 289.9 | M21: 287.06 | O21: Investing Cash Flow | P21: -992.02 | Q21: -161.37 | R21: -193.4 | S21: 733.73 | T21: -1317
H22: Total Long-Term Liabilities | I22: 272.76 | J22: 266.09 | K22: 296.09 | L22: 663.85 | M22: 287.06 | O22: Short-Term Debt (Net) | P22: 0 | Q22: 0.08 | R22: -13.91 | S22: 366.78 | T22: -385.34
H23: Total Liabilities | I23: 1238 | J23: 1268 | K23: 1458 | L23: 1761 | M23: 1735 | O23: Long-Term Debt (Net) | P23: 2.93 | Q23: 0 | R23: 0 | S23: 0 | T23: 0
H24: Common Stock | I24: 3.2 | J24: 6.42 | K24: 5.61 | L24: 5.63 | M24: 5.67 | O24: Issuance of Common Stock | P24: 45.72 | Q24: 64.02 | R24: 130.27 | S24: 78.97 | T24: 164.57
H25: Treasury Stock | I25: -5829 | J25: -6600 | K25: -2566 | L25: -6372 | M25: -6476 | O25: Repurchase of Common Stock | P25: -13.83 | Q25: -771.03 | R25: -658.95 | S25: -3772 | T25: -103.65
H26: Additional Paid-in Capital | I26: 4653 | J26: 4777 | K26: 4975 | L26: 5145 | M26: 5431 | O26: Other Financing Activities | P26: 0 | Q26: 0 | R26: 0 | S26: -2.9 | T26: 0
H27: AOCI | I27: -69.17 | J27: -159.07 | K27: -125.34 | L27: -269.49 | M27: -60.84 | O27: Financing Cash Flow | P27: 34.82 | Q27: -706.94 | R27: -542.6 | S27: -3329 | T27: -324.42
... H30: Total Liabilities & Equity | I30: 7805 | J30: 8293 | K30: 9687 | L30: 7719 | M30: 9989 | O30: Free Cash Flow | P30: 1112 | Q30: 698.97 | R30: 1496 | S30: 1664 | T30: 1966
H31: Total Debt | I31: 0 | J31: 0 | K31: 0 | L31: 373.95 | M31: 0
H32: Net Cash (Debt) | I32: 3076 | J32: 2669 | K32: 3253 | L32: 1159 | M32: 2765
H33: Book Value | I33: 6567 | J33: 7025 | K33: 8229 | L33: 5958 | M33: 8254
H34: Tangible Book Value | I34: 4163 | J34: 4387 | K34: 5384 | L34: 3212 | M34: 5543

Sheet P&L Statement
B1: MONSTER BEVERAGE CORPORATION — Income Statement (P&L)
B2: Figures in USD millions | Fiscal Year ending December 31
B3: Line Item | C3: FY 2021 | D3: FY 2022 | E3: FY 2023 | F3: FY 2024 | G3: FY 2025 | H3: CAGR (21–25)
B4: REVENUE
B5: Revenue (Net Sales) | C5: =_RawData!B2 -> 5541 | D5: =_RawData!C2 -> 6311 | E5: =_RawData!D2 -> 7140 | F5: =_RawData!E2 -> 7493 | G5: =_RawData!F2 -> 8294 | H5: =(_RawData!F2/_RawData!B2)^(1/4)-1 -> 0.10609892
B6: Revenue Growth (YoY) | C6: ="-" -> - | D6: =(_RawData!C2/_RawData!B2)-1 -> 0.13896409 | E6: =(_RawData!D2/_RawData!C2)-1 -> 0.13135795 | F6: =(_RawData!E2/_RawData!D2)-1 -> 0.049439776 | G6: =(_RawData!F2/_RawData!E2)-1 -> 0.10689977 | H6: =((_RawData!F2/_RawData!B2)^(1/4))-1 -> 0.10609892
B7: COSTS & EXPENSES
B8: Cost of Revenue (COGS) | C8: =_RawData!B3 -> 2433 | D8: =_RawData!C3 -> 3136 | E8: =_RawData!D3 -> 3346 | F8: =_RawData!E3 -> 3444 | G8: =_RawData!F3 -> 3662 | H8: =(_RawData!F3/_RawData!B3)^(1/4)-1 -> 0.10762834
B9: Gross Profit | C9: =_RawData!B2-_RawData!B3 -> 3108 | D9: =_RawData!C2-_RawData!C3 -> 3175 | E9: =_RawData!D2-_RawData!D3 -> 3794 | F9: =_RawData!E2-_RawData!E3 -> 4049 | G9: =_RawData!F2-_RawData!F3 -> 4632 | H9: =(_RawData!F2-_RawData!F3)/(_RawData!F2) -> 0.55847601
B10: Gross Margin % | C10: =(_RawData!B2-_RawData!B3)/_RawData!B2 -> 0.56090958 | D10: =(_RawData!C2-_RawData!C3)/_RawData!C2 -> 0.50308984 | E10: =(_RawData!D2-_RawData!D3)/_RawData!D2 -> 0.53137255 | F10: =(_RawData!E2-_RawData!E3)/_RawData!E2 -> 0.54037101 | G10: =(_RawData!F2-_RawData!F3)/_RawData!F2 -> 0.55847601 | H10: ="-" -> -
B11: Operating Expenses (SG&A/Other) | C11: =_RawData!B5 -> 1311 | D11: =_RawData!C5 -> 1590 | E11: =_RawData!D5 -> 1841 | F11: =_RawData!E5 -> 2119 | G11: =_RawData!F5 -> 2213 | H11: =(_RawData!F5/_RawData!B5)^(1/4)-1 -> 0.13984207
B12: OPERATING INCOME
B13: Operating Income (EBIT) | C13: =_RawData!B6 -> 1797 | D13: =_RawData!C6 -> 1585 | E13: =_RawData!D6 -> 1953 | F13: =_RawData!E6 -> 1930 | G13: =_RawData!F6 -> 2419 | H13: =(_RawData!F6/_RawData!B6)^(1/4)-1 -> 0.077139489
B14: Operating Margin % | C14: =_RawData!B6/_RawData!B2 -> 0.32430969 | D14: =_RawData!C6/_RawData!C2 -> 0.25114879 | E14: =_RawData!D6/_RawData!D2 -> 0.27352941 | F14: =_RawData!E6/_RawData!E2 -> 0.25757374 | G14: =_RawData!F6/_RawData!F2 -> 0.29165662 | H14: ="-" -> -
B15: BELOW-THE-LINE & NET INCOME
B16: Interest & Non-Operating Income | C16: =_RawData!B7 -> 3.95 | D16: =_RawData!C7 -> -12.76 | E16: =_RawData!D7 -> 115.13 | F16: =_RawData!E7 -> 59.17 | G16: =_RawData!F7 -> 63.18 | H16: =(_RawData!F7/_RawData!B7)^(1/4)-1 -> 0.99984175
B17: Pretax Income | C17: =_RawData!B8 -> 1801 | D17: =_RawData!C8 -> 1572 | E17: =_RawData!D8 -> 2068 | F17: =_RawData!E8 -> 1989 | G17: =_RawData!F8 -> 2483 | H17: =(_RawData!F8/_RawData!B8)^(1/4)-1 -> 0.083591904
B18: Provision for Income Taxes | C18: =_RawData!B9 -> 423.94 | D18: =_RawData!C9 -> 380.34 | E18: =_RawData!D9 -> 437.49 | F18: =_RawData!E9 -> 480.41 | G18: =_RawData!F9 -> 577.1 | H18: =(_RawData!F9/_RawData!B9)^(1/4)-1 -> 0.080156466
B19: Net Income | C19: =_RawData!B8-_RawData!B9 -> 1377.06 | D19: =_RawData!C8-_RawData!C9 -> 1191.66 | E19: =_RawData!D8-_RawData!D9 -> 1630.51 | F19: =_RawData!E8-_RawData!E9 -> 1508.59 | G19: =_RawData!F8-_RawData!F9 -> 1905.9 | H19: =(_RawData!F10/_RawData!B10)^(1/4)-1 -> 0.084526729
B20: Net Profit Margin % | C20: =_RawData!B10/_RawData!B2 -> 0.2485111 | D20: =_RawData!C10/_RawData!C2 -> 0.18887656 | E20: =_RawData!D10/_RawData!D2 -> 0.22843137 | F20: =_RawData!E10/_RawData!E2 -> 0.20138796 | G20: =_RawData!F10/_RawData!F2 -> 0.22968411 | H20: ="-" -> -
B21: PER SHARE & OTHER METRICS
B22: Diluted Shares Outstanding (M) | C22: =_RawData!B11 -> 1071 | D22: =_RawData!C11 -> 1066 | E22: =_RawData!D11 -> 1058 | F22: =_RawData!E11 -> 1013 | G22: =_RawData!F11 -> 984 | H22: =(_RawData!F11/_RawData!B11)^(1/4)-1 -> -0.020957811
B23: EPS (Diluted) | C23: =_RawData!B12 -> 1.29 | D23: =_RawData!C12 -> 1.12 | E23: =_RawData!D12 -> 1.54 | F23: =_RawData!E12 -> 1.49 | G23: =_RawData!F12 -> 1.94 | H23: =(_RawData!F12/_RawData!B12)^(1/4)-1 -> 0.10739614
B24: EBITDA | C24: =_RawData!B13 -> 1848 | D24: =_RawData!C13 -> 1646 | E24: =_RawData!D13 -> 2022 | F24: =_RawData!E13 -> 2011 | G24: =_RawData!F13 -> 2534 | H24: =(_RawData!F13/_RawData!B13)^(1/4)-1 -> 0.082121837
B25: EBITDA Margin % | C25: =_RawData!B13/_RawData!B2 -> 0.33351381 | D25: =_RawData!C13/_RawData!C2 -> 0.26081445 | E25: =_RawData!D13/_RawData!D2 -> 0.28319328 | F25: =_RawData!E13/_RawData!E2 -> 0.26838382 | G25: =_RawData!F13/_RawData!F2 -> 0.30552206 | H25: ="-" -> -
B26: Free Cash Flow | C26: =_RawData!B15 -> 1112 | D26: =_RawData!C15 -> 698.97 | E26: =_RawData!D15 -> 1496 | F26: =_RawData!E15 -> 1664 | G26: =_RawData!F15 -> 1966 | H26: =(_RawData!F15/_RawData!B15)^(1/4)-1 -> 0.15310719
B27: FCF Margin % | C27: =_RawData!B15/_RawData!B2 -> 0.2006858 | D27: =_RawData!C15/_RawData!C2 -> 0.11075424 | E27: =_RawData!D15/_RawData!D2 -> 0.20952381 | F27: =_RawData!E15/_RawData!E2 -> 0.22207394 | G27: =_RawData!F15/_RawData!F2 -> 0.23703882 | H27: ="-" -> -

Sheet Balance Sheet
B1: MONSTER BEVERAGE CORPORATION — Balance Sheet
B2: Figures in USD millions | Fiscal Year ending December 31
B3: Line Item | C3: FY 2021 | D3: FY 2022 | E3: FY 2023 | F3: FY 2024 | G3: FY 2025
B4: ASSETS
B5: Cash & Equivalents | C5: =_RawData!I2 -> 1326 | D5: =_RawData!J2 -> 1307 | E5: =_RawData!K2 -> 2298 | F5: =_RawData!L2 -> 1533 | G5: =_RawData!M2 -> 2088
B6: Short-Term Investments | C6: =_RawData!I3 -> 1750 | D6: =_RawData!J3 -> 1362 | E6: =_RawData!K3 -> 955.61 | F6: =_RawData!L3 -> 0 | G6: =_RawData!M3 -> 677.08
B7: Cash & Short-Term Investments | C7: =_RawData!I4 -> 3076 | D7: =_RawData!J4 -> 2669 | E7: =_RawData!K4 -> 3253 | F7: =_RawData!L4 -> 1533 | G7: =_RawData!M4 -> 2765
B8: Accounts Receivable | C8: =_RawData!I5 -> 896.66 | D8: =_RawData!J5 -> 1016 | E8: =_RawData!K5 -> 1194 | F8: =_RawData!L5 -> 1222 | G8: =_RawData!M5 -> 1618
B9: Inventory | C9: =_RawData!I6 -> 593.36 | D9: =_RawData!J6 -> 935.63 | E9: =_RawData!K6 -> 971.41 | F9: =_RawData!L6 -> 737.11 | G9: =_RawData!M6 -> 799.62
B10: Other Current Assets | C10: =_RawData!I7 -> 115.91 | D10: =_RawData!J7 -> 143.61 | E10: =_RawData!K7 -> 170.35 | F10: =_RawData!L7 -> 149.46 | G10: =_RawData!M7 -> 178.19
B11: Total Current Assets | C11: =_RawData!I8 -> 4682 | D11: =_RawData!J8 -> 4765 | E11: =_RawData!K8 -> 5589 | F11: =_RawData!L8 -> 3642 | G11: =_RawData!M8 -> 5361
B12: NON-CURRENT ASSETS
B13: Net PP&E | C13: =_RawData!I9 -> 313.75 | D13: =_RawData!J9 -> 516.9 | E13: =_RawData!K9 -> 890.8 | F13: =_RawData!L9 -> 1047 | G13: =_RawData!M9 -> 1082
B14: Other Intangible Assets | C14: =_RawData!I10 -> 1072 | D14: =_RawData!J10 -> 1220 | E14: =_RawData!K10 -> 1427 | F14: =_RawData!L10 -> 1414 | G14: =_RawData!M10 -> 1379
B15: Goodwill | C15: =_RawData!I11 -> 1332 | D15: =_RawData!J11 -> 1418 | E15: =_RawData!K11 -> 1418 | F15: =_RawData!L11 -> 1332 | G15: =_RawData!M11 -> 1332
B16: Long-Term Investments | C16: =_RawData!I12 -> 99.42 | D16: =_RawData!J12 -> 61.44 | E16: =_RawData!K12 -> 76.43 | F16: =_RawData!L12 -> 0 | G16: =_RawData!M12 -> 487.33
B17: Other Long-Term Assets | C17: =_RawData!I13 -> 305.47 | D17: =_RawData!J13 -> 311.52 | E17: =_RawData!K13 -> 285.22 | F17: =_RawData!L13 -> 284.67 | G17: =_RawData!M13 -> 348.08
B18: TOTAL ASSETS | C18: =_RawData!I14 -> 7805 | D18: =_RawData!J14 -> 8293 | E18: =_RawData!K14 -> 9687 | F18: =_RawData!L14 -> 7719 | G18: =_RawData!M14 -> 9989
B19: LIABILITIES
B20: Accounts Payable | C20: =_RawData!I15 -> 404.26 | D20: =_RawData!J15 -> 444.27 | E20: =_RawData!K15 -> 564.38 | F20: =_RawData!L15 -> 466.78 | G20: =_RawData!M15 -> 565.97
B21: Accrued Expenses | C21: =_RawData!I16 -> 487.88 | D21: =_RawData!J16 -> 501.09 | E21: =_RawData!K16 -> 540.44 | F21: =_RawData!L16 -> 580.93 | G21: =_RawData!M16 -> 804.18
B22: Unearned Revenue | C22: =_RawData!I17 -> 42.53 | D22: =_RawData!J17 -> 43.31 | E22: =_RawData!K17 -> 41.91 | F22: =_RawData!L17 -> 45.81 | G22: =_RawData!M17 -> 45.32
B23: Other Current Liabilities | C23: =_RawData!I18 -> 30.4 | D23: =_RawData!J18 -> 13.32 | E23: =_RawData!K18 -> 14.96 | F23: =_RawData!L18 -> 4.01 | G23: =_RawData!M18 -> 32.31
B24: Total Current Liabilities | C24: =_RawData!I19 -> 965.08 | D24: =_RawData!J19 -> 1002 | E24: =_RawData!K19 -> 1162 | F24: =_RawData!L19 -> 1098 | G24: =_RawData!M19 -> 1448
B25: NON-CURRENT LIABILITIES
B26: Long-Term Debt | C26: =_RawData!I20 -> 0 | D26: =_RawData!J20 -> 0 | E26: =_RawData!K20 -> 0 | F26: =_RawData!L20 -> 373.95 | G26: =_RawData!M20 -> 0
B27: Other Long-Term Liabilities | C27: =_RawData!I21 -> 272.76 | D27: =_RawData!J21 -> 266.09 | E27: =_RawData!K21 -> 296.09 | F27: =_RawData!L21 -> 289.9 | G27: =_RawData!M21 -> 287.06
B28: Total Long-Term Liabilities | C28: =_RawData!I22 -> 272.76 | D28: =_RawData!J22 -> 266.09 | E28: =_RawData!K22 -> 296.09 | F28: =_RawData!L22 -> 663.85 | G28: =_RawData!M22 -> 287.06
B29: TOTAL LIABILITIES | C29: =_RawData!I23 -> 1238 | D29: =_RawData!J23 -> 1268 | E29: =_RawData!K23 -> 1458 | F29: =_RawData!L23 -> 1761 | G29: =_RawData!M23 -> 1735
B30: SHAREHOLDERS' EQUITY
B31: Common Stock | C31: =_RawData!I24 -> 3.2 | D31: =_RawData!J24 -> 6.42 | E31: =_RawData!K24 -> 5.61 | F31: =_RawData!L24 -> 5.63 | G31: =_RawData!M24 -> 5.67
B32: Treasury Stock | C32: =_RawData!I25 -> -5829 | D32: =_RawData!J25 -> -6600 | E32: =_RawData!K25 -> -2566 | F32: =_RawData!L25 -> -6372 | G32: =_RawData!M25 -> -6476
B33: Additional Paid-in Capital | C33: =_RawData!I26 -> 4653 | D33: =_RawData!J26 -> 4777 | E33: =_RawData!K26 -> 4975 | F33: =_RawData!L26 -> 5145 | G33: =_RawData!M26 -> 5431
B34: AOCI | C34: =_RawData!I27 -> -69.17 | D34: =_RawData!J27 -> -159.07 | E34: =_RawData!K27 -> -125.34 | F34: =_RawData!L27 -> -269.49 | G34: =_RawData!M27 -> -60.84
B35: Retained Earnings | C35: =_RawData!I28 -> 7810 | D35: =_RawData!J28 -> 9001 | E35: =_RawData!K28 -> 5940 | F35: =_RawData!L28 -> 7449 | G35: =_RawData!M28 -> 9354
B36: Total Shareholders' Equity | C36: =_RawData!I29 -> 6567 | D36: =_RawData!J29 -> 7025 | E36: =_RawData!K29 -> 8229 | F36: =_RawData!L29 -> 5958 | G36: =_RawData!M29 -> 8254
B37: TOTAL LIABILITIES & EQUITY | C37: =_RawData!I30 -> 7805 | D37: =_RawData!J30 -> 8293 | E37: =_RawData!K30 -> 9687 | F37: =_RawData!L30 -> 7719 | G37: =_RawData!M30 -> 9989
B38: SUPPLEMENTAL
B39: Total Debt | C39: =_RawData!I31 -> 0 | D39: =_RawData!J31 -> 0 | E39: =_RawData!K31 -> 0 | F39: =_RawData!L31 -> 373.95 | G39: =_RawData!M31 -> 0
B40: Net Cash (Debt) | C40: =_RawData!I32 -> 3076 | D40: =_RawData!J32 -> 2669 | E40: =_RawData!K32 -> 3253 | F40: =_RawData!L32 -> 1159 | G40: =_RawData!M32 -> 2765
...

Sheet Cash Flow Statement
B1: MONSTER BEVERAGE CORPORATION — Cash Flow Statement
B2: Figures in USD millions | Fiscal Year ending December 31
B3: Line Item | C3: FY 2021 | D3: FY 2022 | E3: FY 2023 | F3: FY 2024 | G3: FY 2025
B4: OPERATING ACTIVITIES
B5: Net Income | C5: =_RawData!B10 -> 1377 | D5: =_RawData!C10 -> 1192 | E5: =_RawData!D10 -> 1631 | F5: =_RawData!E10 -> 1509 | G5: =_RawData!F10 -> 1905
B6: Depreciation & Amortization | C6: =_RawData!B14 -> 50.16 | D6: =_RawData!C14 -> 61.24 | E6: =_RawData!D14 -> 68.9 | F6: =_RawData!E14 -> 80.43 | G6: =_RawData!F14 -> 114.44
B7: Stock-Based Compensation | C7: =_RawData!P4 -> 70.48 | D7: =_RawData!Q4 -> 64.11 | E7: =_RawData!R4 -> 68.84 | F7: =_RawData!S4 -> 90.99 | G7: =_RawData!T4 -> 125.69
B8: Other Adjustments | C8: =_RawData!P5 -> 19.52 | D8: =_RawData!Q5 -> 57.53 | E8: =_RawData!R5 -> -21.61 | F8: =_RawData!S5 -> 170.94 | G8: =_RawData!T5 -> 72.83
B9: Change in Receivables | C9: =_RawData!P6 -> -254.23 | D9: =_RawData!Q6 -> -128.98 | E9: =_RawData!R6 -> -163.16 | F9: =_RawData!S6 -> -93.92 | G9: =_RawData!T6 -> -300.6
B10: Changes in Inventories | C10: =_RawData!P7 -> -277.79 | D10: =_RawData!Q7 -> -347.71 | E10: =_RawData!R7 -> 7.9 | F10: =_RawData!S7 -> 211.5 | G10: =_RawData!T7 -> -34.92
B11: Changes in Accounts Payable | C11: =_RawData!P8 -> 114.3 | D11: =_RawData!Q8 -> 49.77 | E11: =_RawData!R8 -> 112.79 | F11: =_RawData!S8 -> -61.49 | G11: =_RawData!T8 -> 78.46
B12: Changes in Accrued Expenses | C12: =_RawData!P9 -> 111.13 | D12: =_RawData!Q9 -> 24.13 | E12: =_RawData!R9 -> 11.42 | F12: =_RawData!S9 -> 34.05 | G12: =_RawData!T9 -> 197.41
B13: Other Working Capital Changes | C13: =_RawData!P12 -> -39.77 | D13: =_RawData!Q12 -> -47.25 | E13: =_RawData!R12 -> -6.1 | F13: =_RawData!S12 -> 25.41 | G13: =_RawData!T12 -> -65.34
B14: Operating Cash Flow (CFO) | C14: =_RawData!P13 -> 1156 | D14: =_RawData!Q13 -> 887.7 | E14: =_RawData!R13 -> 1718 | F14: =_RawData!S13 -> 1929 | G14: =_RawData!T13 -> 2098
B15: INVESTING ACTIVITIES
B16: Capital Expenditures (CapEx) | C16: =_RawData!P14 -> -43.87 | D16: =_RawData!Q14 -> -188.73 | E16: =_RawData!R14 -> -221.43 | F16: =_RawData!S14 -> -264.07 | G16: =_RawData!T14 -> -132.28
B17: Sale of PP&E | C17: =_RawData!P15 -> 1.33 | D17: =_RawData!Q15 -> 1.31 | E17: =_RawData!R15 -> 2.52 | F17: =_RawData!S15 -> 2.73 | G17: =_RawData!T15 -> 4.3
B18: Purchases of Investments | C18: =_RawData!P17 -> -2413 | D18: =_RawData!Q17 -> -1847 | E18: =_RawData!R17 -> -1621 | F18: =_RawData!S17 -> -342.12 | G18: =_RawData!T17 -> -1269
B19: Proceeds from Sale of Investments | C19: =_RawData!P18 -> 1489 | D19: =_RawData!Q18 -> 2252 | E19: =_RawData!R18 -> 2030 | F19: =_RawData!S18 -> 1378 | G19: =_RawData!T18 -> 105.79
B20: Business Acquisitions | C20: =_RawData!P19 -> 0 | D20: =_RawData!Q19 -> -329.47 | E20: =_RawData!R19 -> -363.39 | F20: =_RawData!S19 -> 0 | G20: =_RawData!T19 -> 0
B21: Investing Cash Flow (CFI) | C21: =_RawData!P21 -> -992.02 | D21: =_RawData!Q21 -> -161.37 | E21: =_RawData!R21 -> -193.4 | F21: =_RawData!S21 -> 733.73 | G21: =_RawData!T21 -> -1317
B22: FINANCING ACTIVITIES
B23: Short-Term Debt (Net) | C23: =_RawData!P22 -> 0 | D23: =_RawData!Q22 -> 0.08 | E23: =_RawData!R22 -> -13.91 | F23: =_RawData!S22 -> 366.78 | G23: =_RawData!T22 -> -385.34
B24: Issuance of Common Stock | C24: =_RawData!P24 -> 45.72 | D24: =_RawData!Q24 -> 64.02 | E24: =_RawData!R24 -> 130.27 | F24: =_RawData!S24 -> 78.97 | G24: =_RawData!T24 -> 164.57
B25: Repurchase of Common Stock | C25: =_RawData!P25 -> -13.83 | D25: =_RawData!Q25 -> -771.03 | E25: =_RawData!R25 -> -658.95 | F25: =_RawData!S25 -> -3772 | G25: =_RawData!T25 -> -103.65
B26: Financing Cash Flow (CFF) | C26: =_RawData!P27 -> 34.82 | D26: =_RawData!Q27 -> -706.94 | E26: =_RawData!R27 -> -542.6 | F26: =_RawData!S27 -> -3329 | G26: =_RawData!T27 -> -324.42
B27: SUMMARY
B28: Effect of Exchange Rate | C28: =_RawData!P28 -> -52.49 | D28: =_RawData!Q28 -> -38.72 | E28: =_RawData!R28 -> 8.78 | F28: =_RawData!S28 -> -97.62 | G28: =_RawData!T28 -> 97.85
B29: Net Change in Cash | C29: =_RawData!P29 -> 146.05 | D29: =_RawData!Q29 -> -19.32 | E29: =_RawData!R29 -> 990.53 | F29: =_RawData!S29 -> -764.39 | G29: =_RawData!T29 -> 554.83
B30: Free Cash Flow (FCO - CapEx) | C30: =_RawData!B15 -> 1112 | D30: =_RawData!C15 -> 698.97 | E30: =_RawData!D15 -> 1496 | F30: =_RawData!E15 -> 1664 | G30: =_RawData!F15 -> 1966
B31: FCF Margin % | C31: =_RawData!B15/_RawData!B2 -> 0.2006858 | D31: =_RawData!C15/_RawData!C2 -> 0.11075424 | E31: =_RawData!D15/_RawData!D2 -> 0.20952381 | F31: =_RawData!E15/_RawData!E2 -> 0.22207394 | G31: =_RawData!F15/_RawData!F2 -> 0.23703882

Sheet Ratio Analysis
B1: MONSTER BEVERAGE CORPORATION — Ratio Analysis
B3: Ratio | C3: FY 2021 | D3: FY 2022 | E3: FY 2023 | F3: FY 2024 | G3: FY 2025
B4: I. LIQUIDITY RATIOS
B5: Current Ratio | C5: =_RawData!I8/_RawData!I19 -> 4.8514113 | D5: =_RawData!J8/_RawData!J19 -> 4.755489 | E5: =_RawData!K8/_RawData!K19 -> 4.8098107 | F5: =_RawData!L8/_RawData!L19 -> 3.3169399 | G5: =_RawData!M8/_RawData!M19 -> 3.7023481
B6: Quick Ratio | C6: =(_RawData!I8-_RawData!I6)/_RawData!I19 -> 4.2365814 | D6: =(_RawData!J8-_RawData!J6)/_RawData!J19 -> 3.8217265 | E6: =(_RawData!K8-_RawData!K6)/_RawData!K19 -> 3.9738296 | F6: =(_RawData!L8-_RawData!L6)/_RawData!L19 -> 2.6456193 | G6: =(_RawData!M8-_RawData!M6)/_RawData!M19 -> 3.1501243
B7: Cash Ratio | C7: =_RawData!I4/_RawData!I19 -> 3.1873005 | D7: =_RawData!J4/_RawData!J19 -> 2.6636727 | E7: =_RawData!K4/_RawData!K19 -> 2.7994836 | F7: =_RawData!L4/_RawData!L19 -> 1.3961749 | G7: =_RawData!M4/_RawData!M19 -> 1.9095304
B8: II. PROFITABILITY RATIOS
B9: Gross Margin | C9: =(_RawData!B2-_RawData!B3)/_RawData!B2 -> 0.56090958 | D9: =(_RawData!C2-_RawData!C3)/_RawData!C2 -> 0.50308984 | E9: =(_RawData!D2-_RawData!D3)/_RawData!D2 -> 0.53137255 | F9: =(_RawData!E2-_RawData!E3)/_RawData!E2 -> 0.54037101 | G9: =(_RawData!F2-_RawData!F3)/_RawData!F2 -> 0.55847601
B10: Operating Margin (EBIT Margin) | C10: =_RawData!B6/_RawData!B2 -> 0.32430969 | D10: =_RawData!C6/_RawData!C2 -> 0.25114879 | E10: =_RawData!D6/_RawData!D2 -> 0.27352941 | F10: =_RawData!E6/_RawData!E2 -> 0.25757374 | G10: =_RawData!F6/_RawData!F2 -> 0.29165662
B11: Net Profit Margin | C11: =_RawData!B10/_RawData!B2 -> 0.2485111 | D11: =_RawData!C10/_RawData!C2 -> 0.18887656 | E11: =_RawData!D10/_RawData!D2 -> 0.22843137 | F11: =_RawData!E10/_RawData!E2 -> 0.20138796 | G11: =_RawData!F10/_RawData!F2 -> 0.22968411
B12: EBITDA Margin | C12: =_RawData!B13/_RawData!B2 -> 0.33351381 | D12: =_RawData!C13/_RawData!C2 -> 0.26081445 | E12: =_RawData!D13/_RawData!D2 -> 0.28319328 | F12: =_RawData!E13/_RawData!E2 -> 0.26838382 | G12: =_RawData!F13/_RawData!F2 -> 0.30552206
B13: Return on Assets (ROA) | C13: =_RawData!B10/_RawData!I14 -> 0.17642537 | D13: =_RawData!C10/_RawData!J14 -> 0.14373568 | E13: =_RawData!D10/_RawData!K14 -> 0.16836998 | F13: =_RawData!E10/_RawData!L14 -> 0.19549164 | G13: =_RawData!F10/_RawData!M14 -> 0.19070978
B14: Return on Equity (ROE) | C14: =_RawData!B10/_RawData!I29 -> 0.20968479 | D14: =_RawData!C10/_RawData!J29 -> 0.16967972 | E14: =_RawData!D10/_RawData!K29 -> 0.19820148 | F14: =_RawData!E10/_RawData!L29 -> 0.25327291 | G14: =_RawData!F10/_RawData!M29 -> 0.23079719
B15: FCF Margin | C15: =_RawData!B15/_RawData!B2 -> 0.2006858 | D15: =_RawData!C15/_RawData!C2 -> 0.11075424 | E15: =_RawData!D15/_RawData!D2 -> 0.20952381 | F15: =_RawData!E15/_RawData!E2 -> 0.22207394 | G15: =_RawData!F15/_RawData!F2 -> 0.23703882
B16: III. SOLVENCY / LEVERAGE RATIOS
B17: Debt-to-Equity Ratio | C17: =_RawData!I23/_RawData!I29 -> 0.18851835 | D17: =_RawData!J23/_RawData!J29 -> 0.18049822 | E17: =_RawData!K23/_RawData!K29 -> 0.17717827 | F17: =_RawData!L23/_RawData!L29 -> 0.29556898 | G17: =_RawData!M23/_RawData!M29 -> 0.21020111
B18: Debt-to-Assets Ratio | C18: =_RawData!I23/_RawData!I14 -> 0.15861627 | D18: =_RawData!J23/_RawData!J14 -> 0.15290004 | E18: =_RawData!K23/_RawData!K14 -> 0.15051099 | F18: =_RawData!L23/_RawData!L14 -> 0.22813836 | G18: =_RawData!M23/_RawData!M14 -> 0.17369106
B19: Interest Coverage (EBIT/Int.) | C19: =IF(_RawData!B7>0,_RawData!B6/_RawData!B7,"N/A") -> 454.93671 | D19: =IF(_RawData!C7>0,_RawData!C6/_RawData!C7,"N/A") -> N/A | E19: =IF(_RawData!D7>0,_RawData!D6/_RawData!D7,"N/A") -> 16.963433 | F19: =IF(_RawData!E7>0,_RawData!E6/_RawData!E7,"N/A") -> 32.617881 | G19: =IF(_RawData!F7>0,_RawData!F6/_RawData!F7,"N/A") -> 38.287433
B20: Net Debt / EBITDA | C20: =IF(_RawData!I32>0,"Net Cash",(-_RawData!I32)/_RawData!B13) -> Net Cash | D20: =IF(_RawData!J32>0,"Net Cash",(-_RawData!J32)/_RawData!C13) -> Net Cash | E20: =IF(_RawData!K32>0,"Net Cash",(-_RawData!K32)/_RawData!D13) -> Net Cash | F20: =IF(_RawData!L32>0,"Net Cash",(-_RawData!L32)/_RawData!E13) -> Net Cash | G20: =IF(_RawData!M32>0,"Net Cash",(-_RawData!M32)/_RawData!F13) -> Net Cash
B21: IV. EFFICIENCY RATIOS
B22: Asset Turnover | C22: =_RawData!B2/_RawData!I14 -> 0.70992953 | D22: =_RawData!C2/_RawData!J14 -> 0.76100326 | E22: =_RawData!D2/_RawData!K14 -> 0.7370703 | F22: =_RawData!E2/_RawData!L14 -> 0.9707216 | G22: =_RawData!F2/_RawData!M14 -> 0.83031334
B23: Inventory Turnover | C23: =_RawData!B3/_RawData!I6 -> 4.1003775 | D23: =_RawData!C3/_RawData!J6 -> 3.3517523 | E23: =_RawData!D3/_RawData!K6 -> 3.4444776 | F23: =_RawData!E3/_RawData!L6 -> 4.6723013 | G23: =_RawData!F3/_RawData!M6 -> 4.5796753
B24: Receivables Turnover | C24: =_RawData!B2/_RawData!I5 -> 6.1795998 | D24: =_RawData!C2/_RawData!J5 -> 6.2116142 | E24: =_RawData!D2/_RawData!K5 -> 5.9798995 | F24: =_RawData!E2/_RawData!L5 -> 6.1317512 | G24: =_RawData!F2/_RawData!M5 -> 5.1260816
B25: Days Sales Outstanding (DSO) | C25: =365/(_RawData!B2/_RawData!I5) -> 59.065313 | D25: =365/(_RawData!C2/_RawData!J5) -> 58.760894 | E25: =365/(_RawData!D2/_RawData!K5) -> 61.037815 | F25: =365/(_RawData!E2/_RawData!L5) -> 59.526224 | G25: =365/(_RawData!F2/_RawData!M5) -> 71.204485
B26: Days Inventory Outstanding (DIO) | C26: =365/(_RawData!B3/_RawData!I6) -> 89.016194 | D26: =365/(_RawData!C3/_RawData!J6) -> 108.89826 | E26: =365/(_RawData!D3/_RawData!K6) -> 105.96672 | F26: =365/(_RawData!E3/_RawData!L6) -> 78.119962 | G26: =365/(_RawData!F3/_RawData!M6) -> 79.699973
B27: Days Payable Outstanding (DPO) | C27: =365/(_RawData!B3/_RawData!I15) -> 60.647308 | D27: =365/(_RawData!C3/_RawData!J15) -> 51.708721 | E27: =365/(_RawData!D3/_RawData!K15) -> 61.56566 | F27: =365/(_RawData!E3/_RawData!L15) -> 49.470006 | G27: =365/(_RawData!F3/_RawData!M15) -> 56.411537
B28: Cash Conversion Cycle (CCC) | C28: =(365/(_RawData!B2/_RawData!I5))+(365/(_RawData!B3/_RawData!I6))-(365/(_RawData!B3/_RawData!I15)) -> 87.434199 | D28: =(365/(_RawData!C2/_RawData!J5))+(365/(_RawData!C3/_RawData!J6))-(365/(_RawData!C3/_RawData!J15)) -> 115.95043 | E28: =(365/(_RawData!D2/_RawData!K5))+(365/(_RawData!D3/_RawData!K6))-(365/(_RawData!D3/_RawData!K15)) -> 105.43888 | F28: =(365/(_RawData!E2/_RawData!L5))+(365/(_RawData!E3/_RawData!L6))-(365/(_RawData!E3/_RawData!L15)) -> 88.176181 | G28: =(365/(_RawData!F2/_RawData!M5))+(365/(_RawData!F3/_RawData!M6))-(365/(_RawData!F3/_RawData!M15)) -> 94.49292
B29: V. GROWTH RATIOS
B30: Revenue Growth YoY | C30: ="-" -> - | D30: =(_RawData!C2/_RawData!B2)-1 -> 0.13896409 | E30: =(_RawData!D2/_RawData!C2)-1 -> 0.13135795 | F30: =(_RawData!E2/_RawData!D2)-1 -> 0.049439776 | G30: =(_RawData!F2/_RawData!E2)-1 -> 0.10689977
B31: Net Income Growth YoY | C31: ="-" -> - | D31: =(_RawData!C10/_RawData!B10)-1 -> -0.13435004 | E31: =(_RawData!D10/_RawData!C10)-1 -> 0.36828859 | F31: =(_RawData!E10/_RawData!D10)-1 -> -0.074800736 | G31: =(_RawData!F10/_RawData!E10)-1 -> 0.26242545
B32: EPS Growth YoY | C32: ="-" -> - | D32: =(_RawData!C12/_RawData!B12)-1 -> -0.13178295 | E32: =(_RawData!D12/_RawData!C12)-1 -> 0.375 | F32: =(_RawData!E12/_RawData!D12)-1 -> -0.032467532 | G32: =(_RawData!F12/_RawData!E12)-1 -> 0.30201342
B33: FCF Growth YoY | C33: ="-" -> - | D33: =(_RawData!C15/_RawData!B15)-1 -> -0.37142986 | E33: =(_RawData!D15/_RawData!C15)-1 -> 1.1402921 | F33: =(_RawData!E15/_RawData!D15)-1 -> 0.11229947 | G33: =(_RawData!F15/_RawData!E15)-1 -> 0.18149038

Sheet Trend Analysis
B1: MONSTER BEVERAGE CORPORATION — Trend Analysis (Index-Based)
B2: Base Year = FY 2021 (Index = 100). Index = Current Year / Base Year × 100
B3: Metric | C3: FY 2021 | D3: FY 2022 | E3: FY 2023 | F3: FY 2024 | G3: FY 2025
B4: REVENUE & PROFITABILITY TRENDS
B5: Revenue | C5: =_RawData!B2/_RawData!B2*100 -> 100 | D5: =_RawData!C2/_RawData!B2*100 -> 113.89641 | E5: =_RawData!D2/_RawData!B2*100 -> 128.85761 | F5: =_RawData!E2/_RawData!B2*100 -> 135.2283 | G5: =_RawData!F2/_RawData!B2*100 -> 149.68417
B6: Gross Profit | C6: =_RawData!B4/_RawData!B4*100 -> 100 | D6: =_RawData!C4/_RawData!B4*100 -> 102.12287 | E6: =_RawData!D4/_RawData!B4*100 -> 122.03281 | F6: =_RawData!E4/_RawData!B4*100 -> 130.2348 | G6: =_RawData!F4/_RawData!B4*100 -> 148.98681
B7: Operating Income | C7: =_RawData!B6/_RawData!B6*100 -> 100 | D7: =_RawData!C6/_RawData!B6*100 -> 88.20256 | E7: =_RawData!D6/_RawData!B6*100 -> 108.68114 | F7: =_RawData!E6/_RawData!B6*100 -> 107.40122 | G7: =_RawData!F6/_RawData!B6*100 -> 134.61324
B8: Net Income | C8: =_RawData!B10/_RawData!B10*100 -> 100 | D8: =_RawData!C10/_RawData!B10*100 -> 86.564996 | E8: =_RawData!D10/_RawData!B10*100 -> 118.4459 | F8: =_RawData!E10/_RawData!B10*100 -> 109.58606 | G8: =_RawData!F10/_RawData!B10*100 -> 138.34423
B9: EBITDA | C9: =_RawData!B13/_RawData!B13*100 -> 100 | D9: =_RawData!C13/_RawData!B13*100 -> 89.069264 | E9: =_RawData!D13/_RawData!B13*100 -> 109.41558 | F9: =_RawData!E13/_RawData!B13*100 -> 108.82035 | G9: =_RawData!F13/_RawData!B13*100 -> 137.12121
B10: Free Cash Flow | C10: =_RawData!B15/_RawData!B15*100 -> 100 | D10: =_RawData!C15/_RawData!B15*100 -> 62.857014 | E10: =_RawData!D15/_RawData!B15*100 -> 134.53237 | F10: =_RawData!E15/_RawData!B15*100 -> 149.64029 | G10: =_RawData!F15/_RawData!B15*100 -> 176.79856
B11: BALANCE SHEET TRENDS
B12: Total Assets | C12: =_RawData!I14/_RawData!I14*100 -> 100 | D12: =_RawData!J14/_RawData!I14*100 -> 106.2524 | E12: =_RawData!K14/_RawData!I14*100 -> 124.11275 | F12: =_RawData!L14/_RawData!I14*100 -> 98.898142 | G12: =_RawData!M14/_RawData!I14*100 -> 127.98206
B13: Total Current Assets | C13: =_RawData!I8/_RawData!I8*100 -> 100 | D13: =_RawData!J8/_RawData!I8*100 -> 101.77275 | E13: =_RawData!K8/_RawData!I8*100 -> 119.37206 | F13: =_RawData!L8/_RawData!I8*100 -> 77.78727 | G13: =_RawData!M8/_RawData!I8*100 -> 114.50235
B14: Total Liabilities | C14: =_RawData!I23/_RawData!I23*100 -> 100 | D14: =_RawData!J23/_RawData!I23*100 -> 102.42326 | E14: =_RawData!K23/_RawData!I23*100 -> 117.7706 | F14: =_RawData!L23/_RawData!I23*100 -> 142.24556 | G14: =_RawData!M23/_RawData!I23*100 -> 140.1454
B15: Shareholders Equity | C15: =_RawData!I29/_RawData!I29*100 -> 100 | D15: =_RawData!J29/_RawData!I29*100 -> 106.97427 | E15: =_RawData!K29/_RawData!I29*100 -> 125.30836 | F15: =_RawData!L29/_RawData!I29*100 -> 90.726359 | G15: =_RawData!M29/_RawData!I29*100 -> 125.68905
B16: Net Cash (Debt) | C16: =_RawData!I32/_RawData!I32*100 -> 100 | D16: =_RawData!J32/_RawData!I32*100 -> 86.768531 | E16: =_RawData!K32/_RawData!I32*100 -> 105.75423 | F16: =_RawData!L32/_RawData!I32*100 -> 37.678804 | G16: =_RawData!M32/_RawData!I32*100 -> 89.889467
B17: CASH FLOW TRENDS
B18: Operating Cash Flow | C18: =_RawData!P13/_RawData!P13*100 -> 100 | D18: =_RawData!Q13/_RawData!P13*100 -> 76.790657 | E18: =_RawData!R13/_RawData!P13*100 -> 148.61592 | F18: =_RawData!S13/_RawData!P13*100 -> 166.86851 | G18: =_RawData!T13/_RawData!P13*100 -> 181.48789
B19: Capital Expenditures | C19: =_RawData!P14/_RawData!P14*100 -> 100 | D19: =_RawData!Q14/_RawData!P14*100 -> 430.20287 | E19: =_RawData!R14/_RawData!P14*100 -> 504.74128 | F19: =_RawData!S14/_RawData!P14*100 -> 601.93754 | G19: =_RawData!T14/_RawData!P14*100 -> 301.52724
B20: Free Cash Flow | C20: =_RawData!B15/_RawData!B15*100 -> 100 | D20: =_RawData!C15/_RawData!B15*100 -> 62.857014 | E20: =_RawData!D15/_RawData!B15*100 -> 134.53237 | F20: =_RawData!E15/_RawData!B15*100 -> 149.64029 | G20: =_RawData!F15/_RawData!B15*100 -> 176.79856
B21: MARGIN TRENDS (%)
B22: Gross Margin % | C22: =(_RawData!B2-_RawData!B3)/_RawData!B2 -> 0.56090958 | D22: =(_RawData!C2-_RawData!C3)/_RawData!C2 -> 0.50308984 | E22: =(_RawData!D2-_RawData!D3)/_RawData!D2 -> 0.53137255 | F22: =(_RawData!E2-_RawData!E3)/_RawData!E2 -> 0.54037101 | G22: =(_RawData!F2-_RawData!F3)/_RawData!F2 -> 0.55847601
B23: Operating Margin % | C23: =_RawData!B6/_RawData!B2 -> 0.32430969 | D23: =_RawData!C6/_RawData!C2 -> 0.25114879 | E23: =_RawData!D6/_RawData!D2 -> 0.27352941 | F23: =_RawData!E6/_RawData!E2 -> 0.25757374 | G23: =_RawData!F6/_RawData!F2 -> 0.29165662
B24: Net Margin % | C24: =_RawData!B10/_RawData!B2 -> 0.2485111 | D24: =_RawData!C10/_RawData!C2 -> 0.18887656 | E24: =_RawData!D10/_RawData!D2 -> 0.22843137 | F24: =_RawData!E10/_RawData!E2 -> 0.20138796 | G24: =_RawData!F10/_RawData!F2 -> 0.22968411
B25: EBITDA Margin % | C25: =_RawData!B13/_RawData!B2 -> 0.33351381 | D25: =_RawData!C13/_RawData!C2 -> 0.26081445 | E25: =_RawData!D13/_RawData!D2 -> 0.28319328 | F25: =_RawData!E13/_RawData!E2 -> 0.26838382 | G25: =_RawData!F13/_RawData!F2 -> 0.30552206
B26: FCF Margin % | C26: =_RawData!B15/_RawData!B2 -> 0.2006858 | D26: =_RawData!C15/_RawData!C2 -> 0.11075424 | E26: =_RawData!D15/_RawData!D2 -> 0.20952381 | F26: =_RawData!E15/_RawData!E2 -> 0.22207394 | G26: =_RawData!F15/_RawData!F2 -> 0.23703882

Sheet Projections
B1: MONSTER BEVERAGE CORPORATION — Financial Projections (FY2026E–FY2028E)
B2: Projected figures based on historical trends and stated assumptions. All USD millions.
B3: KEY ASSUMPTIONS
B4: Revenue Growth Rate — FY2026E | C4: 0.09 | D4: Based on 5yr avg -13%; conservatively adjusted downward to 9%
B5: Revenue Growth Rate — FY2027E | C5: 0.085 | D5: Gradual tapering of growth
B6: Revenue Growth Rate — FY2028E | C6: 0.08 | D6: Reflecting mature growth phase
B7: COGS as % of Revenue | C7: 0.442 | D7: FY25 actual: 44.2%; kept stable
B8: Operating Expenses as % of Revenue | C8: 0.267 | D8: FY25 actual: 26.7%
B9: Effective Tax Rate | C9: 0.232 | D9: 5yr avg: -23.3%
B10: D&A as % of Revenue | C10: 0.014 | D10: FY25: 1.4% of revenue
B11: CapEx as % of Revenue | C11: 0.019 | D11: FY25 actuals: lower end -1.6-3.5%
B12: Working Capital Change as % of Revenue | C12: -0.01 | D12: Slight net working capital investment
B13: PROJECTED INCOME STATEMENT
B14: Line Item | C14: FY 2025 (A) | D14: FY 2026E | E14: FY 2027E | F14: FY 2028E | G14: Assumption Note
B15: Revenue | C15: =_RawData!F2 -> 8294 | D15: =C15*(1+$C$4) -> 9040.46 | E15: =D15*(1+$C$5) -> 9808.8991 | F15: =E15*(1+$C$6) -> 10593.611 | G15: Prior Year x (1 + Growth Rate)
B16: Cost of Revenue (COGS) | C16: =_RawData!F3 -> 3662 | D16: =D15*$C$7 -> 3995.8833 | E16: =E15*$C$7 -> 4335.5334 | F16: =F15*$C$7 -> 4682.3761 | G16: Revenue x COGS %
B17: Gross Profit | C17: =_RawData!F4 -> 4632 | D17: =D15-D16 -> 5044.5767 | E17: =E15-E16 -> 5473.3657 | F17: =F15-F16 -> 5911.235 | G17: Revenue minus COGS
B18: Operating Expenses | C18: =_RawData!F5 -> 2213 | D18: =D15*$C$8 -> 2413.8028 | E18: =E15*$C$8 -> 2618.9761 | F18: =F15*$C$8 -> 2828.4941 | G18: Revenue x OpEx %
B19: Operating Income (EBIT) | C19: =_RawData!F6 -> 2419 | D19: =D17-D18 -> 2630.7739 | E19: =E17-E18 -> 2854.3896 | F19: =F17-F18 -> 3082.7408 | G19: Gross Profit minus OpEx
B20: Pretax Income | C20: =_RawData!F8 -> 2483 | D20: =D19*1.025 -> 2696.5432 | E20: =E19*1.025 -> 2925.7494 | F20: =F19*1.025 -> 3159.8093 | G20: EBIT + small non-op income
B21: Provision for Income Taxes | C21: =_RawData!F9 -> 577.1 | D21: =D20*$C$9 -> 625.59802 | E21: =E20*$C$9 -> 678.77386 | F21: =F20*$C$9 -> 733.07576 | G21: Pretax Income x Tax Rate
B22: Net Income | C22: =_RawData!F10 -> 1905 | D22: =D20-D21 -> 2070.9452 | E22: =E20-E21 -> 2246.9755 | F22: =F20-F21 -> 2426.7336 | G22: Pretax Income minus Taxes
B23: EBITDA | C23: =_RawData!F13 -> 2534 | D23: =D19+D15*$C$10 -> 2757.3403 | E23: =E19+E15*$C$10 -> 2991.7142 | F23: =F19+F15*$C$10 -> 3231.0514 | G23: EBIT + D&A
B24: Free Cash Flow | C24: =_RawData!F15 -> 1966 | D24: =D19*(1-$C$9)+D15*$C$10-D15*$C$11+D15*$C$12 -> 1884.8274 | E24: =E19*(1-$C$9)+E15*$C$10-E15*$C$11+E15*$C$12 -> 2045.0378 | F24: =F19*(1-$C$9)+F15*$C$10-F15*$C$11+F15*$C$12 -> 2208.6408 | G24: NOPAT + D&A - CapEx +/- WC
B25: PROJECTED MARGINS
B26: Gross Margin % | C26: =C17/C15 -> 0.55847601 | D26: =D17/D15 -> 0.558 | E26: =E17/E15 -> 0.558 | F26: =F17/F15 -> 0.558
B27: Operating Margin % | C27: =C19/C15 -> 0.29165662 | D27: =D19/D15 -> 0.291 | E27: =E19/E15 -> 0.291 | F27: =F19/F15 -> 0.291
B28: Net Profit Margin % | C28: =C22/C15 -> 0.22968411 | D28: =D22/D15 -> 0.2290752 | E28: =E22/E15 -> 0.2290752 | F28: =F22/F15 -> 0.2290752
B29: EBITDA Margin % | C29: =C23/C15 -> 0.30552206 | D29: =D23/D15 -> 0.305 | E29: =E23/E15 -> 0.305 | F29: =F23/F15 -> 0.305
B30: PROJECTED BALANCE SHEET (SIMPLIFIED)
B31: Line Item | C31: FY 2025 (A) | D31: FY 2026E | E31: FY 2027E | F31: FY 2028E
B32: Cash & Short-Term Investments | C32: =_RawData!M4 -> 2765 | D32: =C32+D24 -> 4649.8274 | E32: =D32+E24 -> 6694.8652 | F32: =E32+F24 -> 8903.506
B33: Total Current Assets | C33: =_RawData!M8 -> 5361 | D33: =D15/_RawData!F2*_RawData!M8 -> 5843.49 | E33: =E15/_RawData!F2*_RawData!M8 -> 6340.1866 | F33: =F15/_RawData!F2*_RawData!M8 -> 6847.4016
B34: Total Assets | C34: =_RawData!M14 -> 9989 | D34: =D15/_RawData!F2*_RawData!M14 -> 10888.01 | E34: =E15/_RawData!F2*_RawData!M14 -> 11813.491 | F34: =F15/_RawData!F2*_RawData!M14 -> 12758.57
B35: Total Shareholders' Equity | C35: =_RawData!M29 -> 8254 | D35: =C35+D22 -> 10324.945 | E35: =D35+E22 -> 12571.921 | F35: =E35+F22 -> 14998.654

Sheet Charts & Dashboard
A1: MONSTER BEVERAGE CORPORATION — Dashboard & Charts
A3: Metric | B3: FY2021 | C3: FY2022 | D3: FY2023 | E3: FY2024 | F3: FY2025 | G3: 5yr CAGR | I3: Gross Margin% | J3: Op Margin% | K3: Net Margin% | L3: FCF Margin%
A4: Revenue ($M) | B4: =_RawData!B2 -> 5541 | C4: =_RawData!C2 -> 6311 | D4: =_RawData!D2 -> 7140 | E4: =_RawData!E2 -> 7493 | F4: =_RawData!F2 -> 8294 | G4: =(_RawData!F2/_RawData!B2)^(1/4)-1 -> 0.10609892 | I4: =(_RawData!B2-_RawData!B3)/_RawData!B2 -> 0.56090958 | J4: =_RawData!B6/_RawData!B2 -> 0.32430969 | K4: =_RawData!B10/_RawData!B2 -> 0.2485111 | L4: =_RawData!B15/_RawData!B2 -> 0.2006858
A5: Gross Profit ($M) | B5: =_RawData!B4 -> 3109 | C5: =_RawData!C4 -> 3175 | D5: =_RawData!D4 -> 3794 | E5: =_RawData!E4 -> 4049 | F5: =_RawData!F4 -> 4632 | G5: =(_RawData!F4/_RawData!B4)^(1/4)-1 -> 0.10480837 | I5: =(_RawData!C2-_RawData!C3)/_RawData!C2 -> 0.50308984 | J5: =_RawData!C6/_RawData!C2 -> 0.25114879 | K5: =_RawData!C10/_RawData!C2 -> 0.18887656 | L5: =_RawData!C15/_RawData!C2 -> 0.11075424
A6: Operating Income ($M) | B6: =_RawData!B6 -> 1797 | C6: =_RawData!C6 -> 1585 | D6: =_RawData!D6 -> 1953 | E6: =_RawData!E6 -> 1930 | F6: =_RawData!F6 -> 2419 | G6: =(_RawData!F6/_RawData!B6)^(1/4)-1 -> 0.077139489 | I6: =(_RawData!D2-_RawData!D3)/_RawData!D2 -> 0.53137255 | J6: =_RawData!D6/_RawData!D2 -> 0.27352941 | K6: =_RawData!D10/_RawData!D2 -> 0.22843137 | L6: =_RawData!D15/_RawData!D2 -> 0.20952381
A7: Net Income ($M) | B7: =_RawData!B10 -> 1377 | C7: =_RawData!C10 -> 1192 | D7: =_RawData!D10 -> 1631 | E7: =_RawData!E10 -> 1509 | F7: =_RawData!F10 -> 1905 | G7: =(_RawData!F10/_RawData!B10)^(1/4)-1 -> 0.084526729 | I7: =(_RawData!E2-_RawData!E3)/_RawData!E2 -> 0.54037101 | J7: =_RawData!E6/_RawData!E2 -> 0.25757374 | K7: =_RawData!E10/_RawData!E2 -> 0.20138796 | L7: =_RawData!E15/_RawData!E2 -> 0.22207394
A8: EBITDA ($M) | B8: =_RawData!B13 -> 1848 | C8: =_RawData!C13 -> 1646 | D8: =_RawData!D13 -> 2022 | E8: =_RawData!E13 -> 2011 | F8: =_RawData!F13 -> 2534 | G8: =(_RawData!F13/_RawData!B13)^(1/4)-1 -> 0.082121837 | I8: =(_RawData!F2-_RawData!F3)/_RawData!F2 -> 0.55847601 | J8: =_RawData!F6/_RawData!F2 -> 0.29165662 | K8: =_RawData!F10/_RawData!F2 -> 0.22968411 | L8: =_RawData!F15/_RawData!F2 -> 0.23703882
A9: Free Cash Flow ($M) | B9: =_RawData!B15 -> 1112 | C9: =_RawData!C15 -> 698.97 | D9: =_RawData!D15 -> 1496 | E9: =_RawData!E15 -> 1664 | F9: =_RawData!F15 -> 1966 | G9: =(_RawData!F15/_RawData!B15)^(1/4)-1 -> 0.15310719
A10: Total Assets ($M) | B10: =_RawData!I14 -> 7805 | C10: =_RawData!J14 -> 8293 | D10: =_RawData!K14 -> 9687 | E10: =_RawData!L14 -> 7719 | F10: =_RawData!M14 -> 9989 | G10: =(_RawData!M14/_RawData!I14)^(1/4)-1 -> 0.063621914
